<?xml version="1.0" encoding="utf-8"?>
<robot name="LCAMP_Robot">
  <link name="center">
    <inertial>
      <origin rpy="0 0 0" xyz="0 0 0" />
      <mass value="50" />
      <inertia ixx="98733.33333333334" ixy="0" ixz="0" iyy="392066.6666666667" iyz="0" izz="456666.6666666667" />
    </inertial>
    <visual>
      <geometry>
        <box size="300 140 64" />
      </geometry>
      <material name="center_material">
        <color rgba="0.6 0.4 0.7 0.5" />
      </material>
    </visual>
    <collision>
      <geometry>
        <box size="300 140 64" />
      </geometry>
    </collision>
  </link>
  <link name="sbFront">
    <inertial>
      <origin rpy="0 0 0" xyz="0 0 0" />
      <mass value="100" />
      <inertia ixx="47466.66666666667" ixy="0" ixz="0" iyy="401633.3333333334" iyz="0" izz="380833.3333333334" />
    </inertial>
    <visual>
      <geometry>
         <mesh filename="d:\Users\kdRupp\Documents\Kooperative Forschung\LCAMP\WP6 CLF\Mobile Robot\CAD-Data\STL-Step-Files\Sensorbox curved_15.STL" scale="1 1 1" />
      </geometry>
      <material name="sbFront_material">
        <color rgba="0.82421875 0.80859375 0.859375 1" />
      </material>
    </visual>
    <collision>
      <geometry>
        <box size="210 40 64" />
      </geometry>
    </collision>
  </link>
  <link name="sbRear">
    <inertial>
      <origin rpy="0 0 0" xyz="0 0 0" />
      <mass value="100" />
      <inertia ixx="47466.66666666667" ixy="0" ixz="0" iyy="401633.3333333334" iyz="0" izz="380833.3333333334" />
    </inertial>
    <visual>
      <geometry>
        <mesh filename="d:\Users\kdRupp\Documents\Kooperative Forschung\LCAMP\WP6 CLF\Mobile Robot\CAD-Data\STL-Step-Files\Sensorbox curved_15.STL" scale="1 1 1" />
      </geometry>
      <material name="sbRear_material">
        <color rgba="0.82421875 0.80859375 0.859375 1" />
      </material>
    </visual>
    <collision>
      <geometry>
        <mesh filename="d:\Users\kdRupp\Documents\Kooperative Forschung\LCAMP\WP6 CLF\Mobile Robot\CAD-Data\STL-Step-Files\Sensorbox curved_15.STL" scale="1 1 1" />
      </geometry>
    </collision>
  </link>
  <link name="hubCup1">
    <inertial>
      <origin rpy="0 0 0" xyz="0 0 0" />
      <mass value="100" />
      <inertia ixx="47466.66666666667" ixy="0" ixz="0" iyy="401633.3333333334" iyz="0" izz="380833.3333333334" />
    </inertial>
    <visual>
      <geometry>
        <mesh filename="d:\Users\kdRupp\Documents\Kooperative Forschung\LCAMP\WP6 CLF\Mobile Robot\DHBW CAD-Data\Wheels\STL-Step-Dateien\Hub_Cup_8.STL" scale="1 1 1" />
      </geometry>
      <material name="hubCup1_material">
        <color rgba="0.53515625 0.80859375 0.9375 1" />
      </material>
    </visual>
	 <visual>
	  <origin xyz="0 0 0.0" rpy="-1.57 0 0"/>
      <geometry>
        <mesh filename="d:\Users\kdRupp\Documents\Kooperative Forschung\LCAMP\WP6 CLF\Mobile Robot\DHBW CAD-Data\Wheels\STL-Step-Dateien\Wheel_Hub.STL" scale="1 1 1" />
      </geometry>
      <material name="hubCup1_material">
        <color rgba="0.53515625 0.80859375 0.9375 1" />
      </material>
    </visual>
    <collision>
      <geometry>
        <mesh filename="d:\Users\kdRupp\Documents\Kooperative Forschung\LCAMP\WP6 CLF\Mobile Robot\DHBW CAD-Data\Wheels\STL-Step-Dateien\Hub_Cup_8.STL" scale="1 1 1" />
      </geometry>
    </collision>
  </link>
  <link name="hubCup2">
    <inertial>
      <origin rpy="0 0 0" xyz="0 0 0" />
      <mass value="100" />
      <inertia ixx="47466.66666666667" ixy="0" ixz="0" iyy="401633.3333333334" iyz="0" izz="380833.3333333334" />
    </inertial>
    <visual>
      <geometry>
        <mesh filename="d:\Users\kdRupp\Documents\Kooperative Forschung\LCAMP\WP6 CLF\Mobile Robot\DHBW CAD-Data\Wheels\STL-Step-Dateien\Hub_Cup_8.STL" scale="1 1 1" />
      </geometry>
      <material name="hubCup2_material">
        <color rgba="0.53515625 0.80859375 0.9375 1" />
      </material>
    </visual>
	 <visual>
	 <origin xyz="0 0 0.0" rpy="-1.57 0 0"/>
      <geometry>
        <mesh filename="d:\Users\kdRupp\Documents\Kooperative Forschung\LCAMP\WP6 CLF\Mobile Robot\DHBW CAD-Data\Wheels\STL-Step-Dateien\Wheel_Hub.STL" scale="1 1 1" />
      </geometry>
      <material name="hubCup1_material">
        <color rgba="0.53515625 0.80859375 0.9375 1" />
      </material>
    </visual>
    <collision>
      <geometry>
        <mesh filename="d:\Users\kdRupp\Documents\Kooperative Forschung\LCAMP\WP6 CLF\Mobile Robot\DHBW CAD-Data\Wheels\STL-Step-Dateien\Hub_Cup_8.STL" scale="1 1 1" />
      </geometry>
    </collision>
  </link>
  <link name="hubCup3">
    <inertial>
      <origin rpy="0 0 0" xyz="0 0 0" />
      <mass value="100" />
      <inertia ixx="47466.66666666667" ixy="0" ixz="0" iyy="401633.3333333334" iyz="0" izz="380833.3333333334" />
    </inertial>
    <visual>
      <geometry>
        <mesh filename="d:\Users\kdRupp\Documents\Kooperative Forschung\LCAMP\WP6 CLF\Mobile Robot\DHBW CAD-Data\Wheels\STL-Step-Dateien\Hub_Cup_8.STL" scale="1 1 1" />
      </geometry>
      <material name="hubCup3_material">
        <color rgba="0.53515625 0.80859375 0.9375 1" />
      </material>
    </visual>
    <collision>
      <geometry>
        <mesh filename="d:\Users\kdRupp\Documents\Kooperative Forschung\LCAMP\WP6 CLF\Mobile Robot\DHBW CAD-Data\Wheels\STL-Step-Dateien\Hub_Cup_8.STL" scale="1 1 1" />
      </geometry>
    </collision>
  </link>
  <link name="hubCup4">
    <inertial>
      <origin rpy="0 0 0" xyz="0 0 0" />
      <mass value="100" />
      <inertia ixx="47466.66666666667" ixy="0" ixz="0" iyy="401633.3333333334" iyz="0" izz="380833.3333333334" />
    </inertial>
    <visual>
      <geometry>
        <mesh filename="d:\Users\kdRupp\Documents\Kooperative Forschung\LCAMP\WP6 CLF\Mobile Robot\DHBW CAD-Data\Wheels\STL-Step-Dateien\Hub_Cup_8.STL" scale="1 1 1" />
      </geometry>
      <material name="hubCup4_material">
        <color rgba="0.53515625 0.80859375 0.9375 1" />
      </material>
    </visual>
    <collision>
      <geometry>
        <mesh filename="d:\Users\kdRupp\Documents\Kooperative Forschung\LCAMP\WP6 CLF\Mobile Robot\DHBW CAD-Data\Wheels\STL-Step-Dateien\Hub_Cup_8.STL" scale="1 1 1" />
      </geometry>
    </collision>
  </link>
  <link name="sbLeft">
    <inertial>
      <origin rpy="0 0 0" xyz="0 0 0" />
      <mass value="50" />
      <inertia ixx="20816.666666666668" ixy="0" ixz="0" iyy="40566.66666666667" iyz="0" izz="53883.333333333336" />
    </inertial>
    <visual>
      <geometry>
        <box size="94 64 30" />
      </geometry>
      <material name="sbLeft_material">
        <color rgba="0.5 0.5 0.5 0.6" />
      </material>
    </visual>
    <collision>
      <geometry>
        <box size="94 64 30" />
      </geometry>
    </collision>
  </link>
  <link name="sbRight">
    <inertial>
      <origin rpy="0 0 0" xyz="0 0 0" />
      <mass value="50" />
      <inertia ixx="20816.666666666668" ixy="0" ixz="0" iyy="40566.66666666667" iyz="0" izz="53883.333333333336" />
    </inertial>
    <visual>
      <geometry>
        <box size="94 64 30" />
      </geometry>
      <material name="sbRight_material">
        <color rgba="0.5 0.5 0.5 0.6" />
      </material>
    </visual>
    <collision>
      <geometry>
        <box size="94 64 30" />
      </geometry>
    </collision>
  </link>
  <link name="wheel_hl">
      <origin rpy="1.57 0 0" xyz="0 0 0" />
    <inertial>
      <mass value="50" />
      <inertia ixx="31200.000000000004" ixy="0" ixz="0" iyy="31200.000000000004" iyz="0" izz="57600" />
    </inertial>
    <visual>
      <geometry>
        <cylinder length="24" radius="48" />
      </geometry>
      <material name="wheel_hl_material">
        <color rgba="0.6 0.7 0.8 0.6" />
      </material>
    </visual>
    <collision>
      <geometry>
        <cylinder length="24" radius="48" />
      </geometry>
    </collision>
  </link>
  <link name="wheel_hr">
    <origin rpy="1.57 0 0" xyz="0 0 0" />
    <inertial>
      <origin rpy="0 0 0" xyz="0 0 0" />
      <mass value="50" />
      <inertia ixx="31200.000000000004" ixy="0" ixz="0" iyy="31200.000000000004" iyz="0" izz="57600" />
    </inertial>
    <visual>
      <geometry>
        <cylinder length="24" radius="48" />
      </geometry>
      <material name="wheel_hr_material">
        <color rgba="0.6 0.7 0.8 0.6" />
      </material>
    </visual>
    <collision>
      <geometry>
        <cylinder length="24" radius="48" />
      </geometry>
    </collision>
  </link>
  <link name="wheel_vl">
    <origin rpy="1.57 0 0" xyz="0 0 0" />
    <inertial>
      <origin rpy="0 0 0" xyz="0 0 0" />
      <mass value="50" />
      <inertia ixx="31200.000000000004" ixy="0" ixz="0" iyy="31200.000000000004" iyz="0" izz="57600" />
    </inertial>
    <visual>
      <geometry>
        <cylinder length="24" radius="48" />
      </geometry>
      <material name="wheel_vl_material">
        <color rgba="0.6 0.7 0.8 0.6" />
      </material>
    </visual>
    <collision>
      <geometry>
        <cylinder length="24" radius="48" />
      </geometry>
    </collision>
  </link>
  <link name="wheel_vr">
    <origin rpy="1.57 0 0" xyz="0 0 0" />
    <inertial>
      <origin rpy="0 0 0" xyz="0 0 0" />
      <mass value="50" />
      <inertia ixx="31200.000000000004" ixy="0" ixz="0" iyy="31200.000000000004" iyz="0" izz="57600" />
    </inertial>
    <visual>
	
      <geometry>
        <cylinder length="24" radius="48" />
      </geometry>
      <material name="wheel_vr_material">
        <color rgba="0.6 0.7 0.8 0.6" />
      </material>
    </visual>
    <collision>
      <geometry>
        <cylinder length="24" radius="48" />
      </geometry>
    </collision>
  </link>
  <joint name="joint_hl" type="continuous">
    <origin rpy="1.57 0 0" xyz="-100 85 0" />
    <parent link="center" />
    <child link="wheel_hl" />
    <axis xyz="0 0 1" />
    <dynamics damping="0.1" friction="0.1" />
  </joint>
  <joint name="joint_hlhc" type="fixed">
    <origin rpy="0 3.141592653589793 0" xyz="0 0 -12" />
    <parent link="wheel_hl" />
    <child link="hubCup1" />
    <axis xyz="0 1 0" />
    <dynamics damping="0.1" friction="0.1" />
  </joint>
  <joint name="joint_hr" type="continuous">
    <origin rpy="1.57 0 0" xyz="-100 -85 0" />
    <parent link="center" />
    <child link="wheel_hr" />
    <axis xyz="0 0 1" />
    <dynamics damping="0.1" friction="0.1" />
  </joint>
  <joint name="joint_hrhc" type="fixed">
    <origin rpy="0 0 0" xyz="0 0 12" />
    <parent link="wheel_hr" />
    <child link="hubCup2" />
    <axis xyz="0 1 0" />
    <dynamics damping="0.1" friction="0.1" />
  </joint>
  <joint name="joint_vl" type="continuous">
    <origin rpy="1.57 0 0" xyz="100 85 0" />
    <parent link="center" />
    <child link="wheel_vl" />
    <axis xyz="0 0 1" />
    <dynamics damping="0.1" friction="0.1" />
  </joint>
  <joint name="joint_vlhc" type="fixed">
    <origin rpy="0 3.141592653589793 0" xyz="0 0 -12" />
    <parent link="wheel_vl" />
    <child link="hubCup3" />
    <axis xyz="0 1 0" />
    <dynamics damping="0.1" friction="0.1" />
  </joint>
  <joint name="joint_vr" type="continuous">
    <origin rpy="1.57 0 0" xyz="100 -85 0" />
    <parent link="center" />
    <child link="wheel_vr" />
    <axis xyz="0 0 1" />
    <dynamics damping="0.1" friction="0.1" />
  </joint>
  <joint name="joint_vrhc" type="fixed">
    <origin rpy="0 0 0" xyz="0 0 12" />
    <parent link="wheel_vr" />
    <child link="hubCup4" />
    <axis xyz="0 1 0" />
    <dynamics damping="0.1" friction="0.1" />
  </joint>
  <joint name="joint_sbFront" type="fixed">
    <origin rpy="-1.5707963267948966 -1.5707963267948966 0" xyz="150 0 -32" />
    <parent link="center" />
    <child link="sbFront" />
    <axis xyz="0 1 0" />
    <dynamics damping="0.1" friction="0.1" />
  </joint>
  <joint name="joint_sbRear" type="fixed">
    <origin rpy="1.5707963267948966 -1.5707963267948966 0" xyz="-150 0 -32" />
    <parent link="center" />
    <child link="sbRear" />
    <axis xyz="0 1 0" />
    <dynamics damping="0.1" friction="0.1" />
  </joint>
  <joint name="joint_sbLeft" type="fixed">
    <origin rpy="1.5707963267948966 0 0" xyz="0 90 0" />
    <parent link="center" />
    <child link="sbLeft" />
    <axis xyz="0 1 0" />
    <dynamics damping="0.1" friction="0.1" />
  </joint>
  <joint name="joint_sbRight" type="fixed">
    <origin rpy="-1.5707963267948966 0 0" xyz="0 -90 0" />
    <parent link="center" />
    <child link="sbRight" />
    <axis xyz="0 1 0" />
    <dynamics damping="0.1" friction="0.1" />
  </joint>
</robot>