<?xml version="1.0" encoding="utf-8"?>
<robot name="LCAMP_Robot">
  <link name="center">
    <inertial>
      <origin rpy="0 0 0" xyz="0 0 0" />
      <mass value="50" />
      <inertia ixx="98733.33333333334" ixy="0" ixz="0" iyy="392066.6666666667" iyz="0" izz="456666.6666666667" />
    </inertial>
    <visual>
      <geometry>
        <box size="300 140 64" />
      </geometry>
      <material name="center_material">
        <color rgba="0.6 0.4 0.7 0.5" />
      </material>
    </visual>
    <collision>
      <geometry>
        <box size="300 140 64" />
      </geometry>
    </collision>
  </link>
  <link name="drive_rl_Omni-Wheel">
    <inertial>
      <origin rpy="0 0 0" xyz="0 0 0" />
      <mass value="100" />
      <inertia ixx="47466.66666666667" ixy="0" ixz="0" iyy="401633.3333333334" iyz="0" izz="380833.3333333334" />
    </inertial>
    <visual name="Wheel-Hub">
      <origin rpy="1.5707963267948966 0 0" xyz="0 0 0" />
      <geometry>
        <mesh filename="d:\Users\kdRupp\Documents\Kooperative Forschung\LCAMP\WP6 CLF\Mobile Robot\DHBW CAD-Data\Wheels\STL-Step-Dateien\Wheel_Hub.STL" scale="1 1 1" />
      </geometry>
      <material name="drive_rl_Omni-Wheel_material">
        <color rgba="1 1 1 0.7" />
      </material>
    </visual>
    <visual name="rim_inner">
      <origin rpy="1.5707963267948966 0 0" xyz="0 0 10" />
      <geometry>
        <mesh filename="d:\Users\kdRupp\Documents\Kooperative Forschung\LCAMP\WP6 CLF\Mobile Robot\DHBW CAD-Data\RegularWheel\Stl-Step-Dateien\Regular_Wheel_Star_30_84.STL" scale="1 1 1" />
      </geometry>
      <material name="drive_rl_Omni-Wheel_material">
        <color rgba="1 1 1 0.7" />
      </material>
    </visual>
    <visual name="rim_outer">
      <origin rpy="1.5707963267948966 0 0" xyz="0 0 20" />
      <geometry>
        <mesh filename="d:\Users\kdRupp\Documents\Kooperative Forschung\LCAMP\WP6 CLF\Mobile Robot\DHBW CAD-Data\RegularWheel\Stl-Step-Dateien\Regular_Wheel_Star_24_84.STL" scale="1 1 1" />
      </geometry>
      <material name="drive_rl_Omni-Wheel_material">
        <color rgba="1 1 1 0.7" />
      </material>
    </visual>
    <visual name="Roller">
      <origin rpy="0 0 0" xyz="0 0 30" />
      <geometry>
        <mesh filename="d:\Users\kdRupp\Documents\Kooperative Forschung\LCAMP\WP6 CLF\Mobile Robot\DHBW CAD-Data\Wheels\STL-Step-Dateien\Hub_Cup_8.STL" scale="1 1 1" />
      </geometry>
      <material name="drive_rl_Omni-Wheel_material">
        <color rgba="1 1 1 0.7" />
      </material>
    </visual>
    <visual name="Roller">
      <origin rpy="1.5707963267948966 0 0" xyz="0 0 40" />
      <geometry>
        <mesh filename="d:\Users\kdRupp\Documents\Kooperative Forschung\LCAMP\WP6 CLF\Mobile Robot\DHBW CAD-Data\RegularWheel\Stl-Step-Dateien\Tire_96.STL" scale="1 1 1" />
      </geometry>
      <material name="drive_rl_Omni-Wheel_material">
        <color rgba="0 0 0 1" />
      </material>
    </visual>
    <collision>
      <geometry>
        <cylinder length="1" radius="1" />
      </geometry>
    </collision>
  </link>
  <link name="jdrive_rl">
    <inertial>
      <origin rpy="0 0 0" xyz="0 0 0" />
      <mass value="50" />
      <inertia ixx="31200.000000000004" ixy="0" ixz="0" iyy="31200.000000000004" iyz="0" izz="57600" />
    </inertial>
    <visual>
      <geometry>
        <cylinder length="24" radius="48" />
      </geometry>
      <material name="jdrive_rl_material">
        <color rgba="0.6 0.7 0.8 0.6" />
      </material>
    </visual>
    <collision>
      <geometry>
        <cylinder length="24" radius="48" />
      </geometry>
    </collision>
  </link>
  <link name="drive_rr_Omni-Wheel">
    <inertial>
      <origin rpy="0 0 0" xyz="0 0 0" />
      <mass value="100" />
      <inertia ixx="47466.66666666667" ixy="0" ixz="0" iyy="401633.3333333334" iyz="0" izz="380833.3333333334" />
    </inertial>
    <visual name="Wheel-Hub">
      <origin rpy="1.5707963267948966 0 0" xyz="0 0 0" />
      <geometry>
        <mesh filename="d:\Users\kdRupp\Documents\Kooperative Forschung\LCAMP\WP6 CLF\Mobile Robot\DHBW CAD-Data\Wheels\STL-Step-Dateien\Wheel_Hub.STL" scale="1 1 1" />
      </geometry>
      <material name="drive_rr_Omni-Wheel_material">
        <color rgba="1 1 1 0.7" />
      </material>
    </visual>
    <visual name="rim_inner">
      <origin rpy="1.5707963267948966 0 0" xyz="0 0 10" />
      <geometry>
        <mesh filename="d:\Users\kdRupp\Documents\Kooperative Forschung\LCAMP\WP6 CLF\Mobile Robot\DHBW CAD-Data\RegularWheel\Stl-Step-Dateien\Regular_Wheel_Star_30_84.STL" scale="1 1 1" />
      </geometry>
      <material name="drive_rr_Omni-Wheel_material">
        <color rgba="1 1 1 0.7" />
      </material>
    </visual>
    <visual name="rim_outer">
      <origin rpy="1.5707963267948966 0 0" xyz="0 0 20" />
      <geometry>
        <mesh filename="d:\Users\kdRupp\Documents\Kooperative Forschung\LCAMP\WP6 CLF\Mobile Robot\DHBW CAD-Data\RegularWheel\Stl-Step-Dateien\Regular_Wheel_Star_24_84.STL" scale="1 1 1" />
      </geometry>
      <material name="drive_rr_Omni-Wheel_material">
        <color rgba="1 1 1 0.7" />
      </material>
    </visual>
    <visual name="Roller">
      <origin rpy="0 0 0" xyz="0 0 30" />
      <geometry>
        <mesh filename="d:\Users\kdRupp\Documents\Kooperative Forschung\LCAMP\WP6 CLF\Mobile Robot\DHBW CAD-Data\Wheels\STL-Step-Dateien\Hub_Cup_8.STL" scale="1 1 1" />
      </geometry>
      <material name="drive_rr_Omni-Wheel_material">
        <color rgba="1 1 1 0.7" />
      </material>
    </visual>
    <visual name="Roller">
      <origin rpy="1.5707963267948966 0 0" xyz="0 0 40" />
      <geometry>
        <mesh filename="d:\Users\kdRupp\Documents\Kooperative Forschung\LCAMP\WP6 CLF\Mobile Robot\DHBW CAD-Data\RegularWheel\Stl-Step-Dateien\Tire_96.STL" scale="1 1 1" />
      </geometry>
      <material name="drive_rr_Omni-Wheel_material">
        <color rgba="0 0 0 1" />
      </material>
    </visual>
    <collision>
      <geometry>
        <cylinder length="1" radius="1" />
      </geometry>
    </collision>
  </link>
  <link name="jdrive_rr">
    <inertial>
      <origin rpy="0 0 0" xyz="0 0 0" />
      <mass value="50" />
      <inertia ixx="31200.000000000004" ixy="0" ixz="0" iyy="31200.000000000004" iyz="0" izz="57600" />
    </inertial>
    <visual>
      <geometry>
        <cylinder length="24" radius="48" />
      </geometry>
      <material name="jdrive_rr_material">
        <color rgba="0.6 0.7 0.8 0.6" />
      </material>
    </visual>
    <collision>
      <geometry>
        <cylinder length="24" radius="48" />
      </geometry>
    </collision>
  </link>
  <link name="drive_fl_Regular-Wheel">
    <inertial>
      <origin rpy="0 0 0" xyz="0 0 0" />
      <mass value="100" />
      <inertia ixx="47466.66666666667" ixy="0" ixz="0" iyy="401633.3333333334" iyz="0" izz="380833.3333333334" />
    </inertial>
    <visual name="Wheel-Hub">
      <origin rpy="1.5707963267948966 0 0" xyz="0 0 0" />
      <geometry>
        <mesh filename="d:\Users\kdRupp\Documents\Kooperative Forschung\LCAMP\WP6 CLF\Mobile Robot\DHBW CAD-Data\Wheels\STL-Step-Dateien\Wheel_Hub.STL" scale="1 1 1" />
      </geometry>
      <material name="drive_fl_Regular-Wheel_material">
        <color rgba="1 1 1 0.7" />
      </material>
    </visual>
    <visual name="rim-inner">
      <origin rpy="1.5707963267948966 0 0" xyz="0 0 10" />
      <geometry>
        <mesh filename="d:\Users\kdRupp\Documents\Kooperative Forschung\LCAMP\WP6 CLF\Mobile Robot\DHBW CAD-Data\RegularWheel\Stl-Step-Dateien\Regular_Wheel_Star_30_84.STL" scale="1 1 1" />
      </geometry>
      <material name="drive_fl_Regular-Wheel_material">
        <color rgba="1 1 1 0.7" />
      </material>
    </visual>
    <visual name="rim-outer">
      <origin rpy="1.5707963267948966 0 0" xyz="0 0 20" />
      <geometry>
        <mesh filename="d:\Users\kdRupp\Documents\Kooperative Forschung\LCAMP\WP6 CLF\Mobile Robot\DHBW CAD-Data\RegularWheel\Stl-Step-Dateien\Regular_Wheel_Star_24_84.STL" scale="1 1 1" />
      </geometry>
      <material name="drive_fl_Regular-Wheel_material">
        <color rgba="1 1 1 0.7" />
      </material>
    </visual>
    <visual name="Wheel-Hub-Cup">
      <origin rpy="0 0 0" xyz="0 0 30" />
      <geometry>
        <mesh filename="d:\Users\kdRupp\Documents\Kooperative Forschung\LCAMP\WP6 CLF\Mobile Robot\DHBW CAD-Data\Wheels\STL-Step-Dateien\Hub_Cup_8.STL" scale="1 1 1" />
      </geometry>
      <material name="drive_fl_Regular-Wheel_material">
        <color rgba="1 1 1 0.7" />
      </material>
    </visual>
    <visual name="Tire">
      <origin rpy="1.5707963267948966 0 0" xyz="0 0 40" />
      <geometry>
        <mesh filename="d:\Users\kdRupp\Documents\Kooperative Forschung\LCAMP\WP6 CLF\Mobile Robot\DHBW CAD-Data\RegularWheel\Stl-Step-Dateien\Tire_96.STL" scale="1 1 1" />
      </geometry>
      <material name="drive_fl_Regular-Wheel_material">
        <color rgba="0 0 0 1" />
      </material>
    </visual>
    <collision>
      <geometry>
        <cylinder length="1" radius="1" />
      </geometry>
    </collision>
  </link>
  <link name="jdrive_fl">
    <inertial>
      <origin rpy="0 0 0" xyz="0 0 0" />
      <mass value="50" />
      <inertia ixx="31200.000000000004" ixy="0" ixz="0" iyy="31200.000000000004" iyz="0" izz="57600" />
    </inertial>
    <visual>
      <geometry>
        <cylinder length="24" radius="48" />
      </geometry>
      <material name="jdrive_fl_material">
        <color rgba="0.6 0.7 0.8 0.6" />
      </material>
    </visual>
    <collision>
      <geometry>
        <cylinder length="24" radius="48" />
      </geometry>
    </collision>
  </link>
  <link name="drive_fr_Regular-Wheel">
    <inertial>
      <origin rpy="0 0 0" xyz="0 0 0" />
      <mass value="100" />
      <inertia ixx="47466.66666666667" ixy="0" ixz="0" iyy="401633.3333333334" iyz="0" izz="380833.3333333334" />
    </inertial>
    <visual name="Wheel-Hub">
      <origin rpy="1.5707963267948966 0 0" xyz="0 0 0" />
      <geometry>
        <mesh filename="d:\Users\kdRupp\Documents\Kooperative Forschung\LCAMP\WP6 CLF\Mobile Robot\DHBW CAD-Data\Wheels\STL-Step-Dateien\Wheel_Hub.STL" scale="1 1 1" />
      </geometry>
      <material name="drive_fr_Regular-Wheel_material">
        <color rgba="1 1 1 0.7" />
      </material>
    </visual>
    <visual name="rim-inner">
      <origin rpy="1.5707963267948966 0 0" xyz="0 0 10" />
      <geometry>
        <mesh filename="d:\Users\kdRupp\Documents\Kooperative Forschung\LCAMP\WP6 CLF\Mobile Robot\DHBW CAD-Data\RegularWheel\Stl-Step-Dateien\Regular_Wheel_Star_30_84.STL" scale="1 1 1" />
      </geometry>
      <material name="drive_fr_Regular-Wheel_material">
        <color rgba="1 1 1 0.7" />
      </material>
    </visual>
    <visual name="rim-outer">
      <origin rpy="1.5707963267948966 0 0" xyz="0 0 20" />
      <geometry>
        <mesh filename="d:\Users\kdRupp\Documents\Kooperative Forschung\LCAMP\WP6 CLF\Mobile Robot\DHBW CAD-Data\RegularWheel\Stl-Step-Dateien\Regular_Wheel_Star_24_84.STL" scale="1 1 1" />
      </geometry>
      <material name="drive_fr_Regular-Wheel_material">
        <color rgba="1 1 1 0.7" />
      </material>
    </visual>
    <visual name="Wheel-Hub-Cup">
      <origin rpy="0 0 0" xyz="0 0 30" />
      <geometry>
        <mesh filename="d:\Users\kdRupp\Documents\Kooperative Forschung\LCAMP\WP6 CLF\Mobile Robot\DHBW CAD-Data\Wheels\STL-Step-Dateien\Hub_Cup_8.STL" scale="1 1 1" />
      </geometry>
      <material name="drive_fr_Regular-Wheel_material">
        <color rgba="1 1 1 0.7" />
      </material>
    </visual>
    <visual name="Tire">
      <origin rpy="1.5707963267948966 0 0" xyz="0 0 40" />
      <geometry>
        <mesh filename="d:\Users\kdRupp\Documents\Kooperative Forschung\LCAMP\WP6 CLF\Mobile Robot\DHBW CAD-Data\RegularWheel\Stl-Step-Dateien\Tire_96.STL" scale="1 1 1" />
      </geometry>
      <material name="drive_fr_Regular-Wheel_material">
        <color rgba="0 0 0 1" />
      </material>
    </visual>
    <collision>
      <geometry>
        <cylinder length="1" radius="1" />
      </geometry>
    </collision>
  </link>
  <link name="jdrive_fr">
    <inertial>
      <origin rpy="0 0 0" xyz="0 0 0" />
      <mass value="50" />
      <inertia ixx="31200.000000000004" ixy="0" ixz="0" iyy="31200.000000000004" iyz="0" izz="57600" />
    </inertial>
    <visual>
      <geometry>
        <cylinder length="24" radius="48" />
      </geometry>
      <material name="jdrive_fr_material">
        <color rgba="0.6 0.7 0.8 0.6" />
      </material>
    </visual>
    <collision>
      <geometry>
        <cylinder length="24" radius="48" />
      </geometry>
    </collision>
  </link>
  <link name="Sensorbox front_sbFront">
    <inertial>
      <origin rpy="0 0 0" xyz="0 0 0" />
      <mass value="100" />
      <inertia ixx="47466.66666666667" ixy="0" ixz="0" iyy="401633.3333333334" iyz="0" izz="380833.3333333334" />
    </inertial>
    <visual>
      <geometry>
        <mesh filename="d:\Users\kdRupp\Documents\Kooperative Forschung\LCAMP\WP6 CLF\Mobile Robot\DHBW CAD-Data\SensorSystems\STL-Step-Files\Sensorbox curved_15.STL" scale="1 1 1" />
      </geometry>
      <material name="Sensorbox front_sbFront_material">
        <color rgba="0.5019607843137255 0.5019607843137255 0.5019607843137255 1" />
      </material>
    </visual>
    <collision>
      <geometry>
        <mesh filename="d:\Users\kdRupp\Documents\Kooperative Forschung\LCAMP\WP6 CLF\Mobile Robot\DHBW CAD-Data\SensorSystems\STL-Step-Files\Sensorbox curved_15.STL" scale="1 1 1" />
      </geometry>
    </collision>
  </link>
  <link name="Sensorbox rear_sbRear">
    <inertial>
      <origin rpy="0 0 0" xyz="0 0 0" />
      <mass value="100" />
      <inertia ixx="47466.66666666667" ixy="0" ixz="0" iyy="401633.3333333334" iyz="0" izz="380833.3333333334" />
    </inertial>
    <visual>
      <geometry>
        <mesh filename="d:\Users\kdRupp\Documents\Kooperative Forschung\LCAMP\WP6 CLF\Mobile Robot\DHBW CAD-Data\SensorSystems\STL-Step-Files\Sensorbox curved_15.STL" scale="1 1 1" />
      </geometry>
      <material name="Sensorbox rear_sbRear_material">
        <color rgba="0.5019607843137255 0.5019607843137255 0.5019607843137255 1" />
      </material>
    </visual>
    <collision>
      <geometry>
        <mesh filename="d:\Users\kdRupp\Documents\Kooperative Forschung\LCAMP\WP6 CLF\Mobile Robot\DHBW CAD-Data\SensorSystems\STL-Step-Files\Sensorbox curved_15.STL" scale="1 1 1" />
      </geometry>
    </collision>
  </link>
  <joint name="joint_drive_rl" type="continuous">
    <origin rpy="1.5707963267948966 0 0" xyz="-100 85 0" />
    <parent link="center" />
    <child link="jdrive_rl" />
    <axis xyz="0 0 1" />
    <dynamics damping="0.1" friction="0.1" />
  </joint>
  <joint name="joint_drive_rl_Omni-Wheel" type="fixed">
    <origin rpy="0 3.141592653589793 0" xyz="0 0 -12" />
    <parent link="jdrive_rl" />
    <child link="drive_rl_Omni-Wheel" />
    <axis xyz="0 0 1" />
    <dynamics damping="0.1" friction="0.1" />
  </joint>
  <joint name="joint_drive_rr" type="continuous">
    <origin rpy="-1.5707963267948966 0 0" xyz="-100 -85 0" />
    <parent link="center" />
    <child link="jdrive_rr" />
    <axis xyz="0 0 1" />
    <dynamics damping="0.1" friction="0.1" />
  </joint>
  <joint name="joint_drive_rr_Omni-Wheel" type="fixed">
    <origin rpy="0 3.141592653589793 0" xyz="0 0 -12" />
    <parent link="jdrive_rr" />
    <child link="drive_rr_Omni-Wheel" />
    <axis xyz="0 0 1" />
    <dynamics damping="0.1" friction="0.1" />
  </joint>
  <joint name="joint_drive_fl" type="continuous">
    <origin rpy="1.5707963267948966 0 0" xyz="100 85 0" />
    <parent link="center" />
    <child link="jdrive_fl" />
    <axis xyz="0 0 1" />
    <dynamics damping="0.1" friction="0.1" />
  </joint>
  <joint name="joint_drive_fl_Regular-Wheel" type="fixed">
    <origin rpy="0 3.141592653589793 0" xyz="0 0 -12" />
    <parent link="jdrive_fl" />
    <child link="drive_fl_Regular-Wheel" />
    <axis xyz="0 0 1" />
    <dynamics damping="0.1" friction="0.1" />
  </joint>
  <joint name="joint_drive_fr" type="continuous">
    <origin rpy="-1.5707963267948966 0 0" xyz="100 -85 0" />
    <parent link="center" />
    <child link="jdrive_fr" />
    <axis xyz="0 0 1" />
    <dynamics damping="0.1" friction="0.1" />
  </joint>
  <joint name="joint_drive_fr_Regular-Wheel" type="fixed">
    <origin rpy="0 3.141592653589793 0" xyz="0 0 -12" />
    <parent link="jdrive_fr" />
    <child link="drive_fr_Regular-Wheel" />
    <axis xyz="0 0 1" />
    <dynamics damping="0.1" friction="0.1" />
  </joint>
  <joint name="link_Sensorbox front_sbFront" type="fixed">
    <origin rpy="-1.5707963267948966 -1.5707963267948966 0" xyz="150 0 -32" />
    <parent link="center" />
    <child link="Sensorbox front_sbFront" />
    <axis xyz="0 0 1" />
    <dynamics damping="0.1" friction="0.1" />
  </joint>
  <joint name="link_Sensorbox rear_sbRear" type="fixed">
    <origin rpy="1.5707963267948966 -1.5707963267948966 0" xyz="-150 0 -32" />
    <parent link="center" />
    <child link="Sensorbox rear_sbRear" />
    <axis xyz="0 0 1" />
    <dynamics damping="0.1" friction="0.1" />
  </joint>
</robot>