<?xml version="1.0" encoding="utf-8"?>
<robot name="LCAMP_Robot">
  <link name="center">
    <inertial>
      <origin rpy="0 0 0" xyz="0 0 0" />
      <mass value="50" />
      <inertia ixx="9.873333333333334E-05" ixy="0" ixz="0" iyy="0.00039206666666666664" iyz="0" izz="0.0004566666666666667" />
    </inertial>
    <visual>
      <geometry>
        <box size="0.3 0.14 0.064" />
      </geometry>
      <material name="center_material">
        <color rgba="0.6 0.4 0.7 0.5" />
      </material>
    </visual>
    <collision>
      <geometry>
        <box size="0.3 0.14 0.064" />
      </geometry>
    </collision>
  </link>
  <link name="drive_rl_Regular-Wheel">
    <inertial>
      <origin rpy="0 0 0" xyz="0 0 0" />
      <mass value="100" />
      <inertia ixx="4.7466666666666664E-05" ixy="0" ixz="0" iyy="0.0004016333333333333" iyz="0" izz="0.00038083333333333323" />
    </inertial>
    <visual name="Wheel-Hub">
      <origin rpy="0 0 0" xyz="0 0 0" />
      <geometry>
        <mesh filename="d:\Users\kdRupp\source\repos\LCAMP\Daten\DHBW CAD-Data\Wheels\STL-Step-Dateien\Wheel_Hub.STL" scale="0.001 0.001 0.001" />
      </geometry>
      <material name="drive_rl_Regular-Wheel_material">
        <color rgba="1 1 1 0.7" />
      </material>
    </visual>
    <visual name="rim-inner">
      <origin rpy="0 0 0" xyz="0 0 0.003" />
      <geometry>
        <mesh filename="d:\Users\kdRupp\source\repos\LCAMP\Daten\DHBW CAD-Data\RegularWheel\Stl-Step-Dateien\Regular_Wheel_Star_30_84.STL" scale="0.001 0.001 0.001" />
      </geometry>
      <material name="drive_rl_Regular-Wheel_material">
        <color rgba="1 1 1 0.7" />
      </material>
    </visual>
    <visual name="rim-outer">
      <origin rpy="0 0 0" xyz="0 0 0.025" />
      <geometry>
        <mesh filename="d:\Users\kdRupp\source\repos\LCAMP\Daten\DHBW CAD-Data\RegularWheel\Stl-Step-Dateien\Regular_Wheel_Star_24_84.STL" scale="0.001 0.001 0.001" />
      </geometry>
      <material name="drive_rl_Regular-Wheel_material">
        <color rgba="1 1 1 0.7" />
      </material>
    </visual>
    <visual name="Wheel-Hub-Cup">
      <origin rpy="0 0 0" xyz="0 0 0.029" />
      <geometry>
        <mesh filename="d:\Users\kdRupp\source\repos\LCAMP\Daten\DHBW CAD-Data\Wheels\STL-Step-Dateien\Hub_Cup_8.STL" scale="0.001 0.001 0.001" />
      </geometry>
      <material name="drive_rl_Regular-Wheel_material">
        <color rgba="1 1 1 0.7" />
      </material>
    </visual>
    <visual name="Tire">
      <origin rpy="0 0 0" xyz="0 0 0.003" />
      <geometry>
        <mesh filename="d:\Users\kdRupp\source\repos\LCAMP\Daten\DHBW CAD-Data\RegularWheel\Stl-Step-Dateien\Tire_96.STL" scale="0.001 0.001 0.001" />
      </geometry>
      <material name="drive_rl_Regular-Wheel_material">
        <color rgba="0 0 0 1" />
      </material>
    </visual>
    <collision>
      <geometry>
        <cylinder length="1" radius="1" />
      </geometry>
    </collision>
  </link>
  <link name="jdrive_rl">
    <inertial>
      <origin rpy="0 0 0" xyz="0 0 0" />
      <mass value="50" />
      <inertia ixx="3.12E-05" ixy="0" ixz="0" iyy="3.12E-05" iyz="0" izz="57.60000000000001" />
    </inertial>
    <visual>
      <geometry>
        <cylinder length="0.024" radius="0.048" />
      </geometry>
      <material name="jdrive_rl_material">
        <color rgba="0.6 0.7 0.8 0.6" />
      </material>
    </visual>
    <collision>
      <geometry>
        <cylinder length="0.024" radius="0.048" />
      </geometry>
    </collision>
  </link>
  <link name="drive_rr_Regular-Wheel">
    <inertial>
      <origin rpy="0 0 0" xyz="0 0 0" />
      <mass value="100" />
      <inertia ixx="4.7466666666666664E-05" ixy="0" ixz="0" iyy="0.0004016333333333333" iyz="0" izz="0.00038083333333333323" />
    </inertial>
    <visual name="Wheel-Hub">
      <origin rpy="0 0 0" xyz="0 0 0" />
      <geometry>
        <mesh filename="d:\Users\kdRupp\source\repos\LCAMP\Daten\DHBW CAD-Data\Wheels\STL-Step-Dateien\Wheel_Hub.STL" scale="0.001 0.001 0.001" />
      </geometry>
      <material name="drive_rr_Regular-Wheel_material">
        <color rgba="1 1 1 0.7" />
      </material>
    </visual>
    <visual name="rim-inner">
      <origin rpy="0 0 0" xyz="0 0 0.003" />
      <geometry>
        <mesh filename="d:\Users\kdRupp\source\repos\LCAMP\Daten\DHBW CAD-Data\RegularWheel\Stl-Step-Dateien\Regular_Wheel_Star_30_84.STL" scale="0.001 0.001 0.001" />
      </geometry>
      <material name="drive_rr_Regular-Wheel_material">
        <color rgba="1 1 1 0.7" />
      </material>
    </visual>
    <visual name="rim-outer">
      <origin rpy="0 0 0" xyz="0 0 0.025" />
      <geometry>
        <mesh filename="d:\Users\kdRupp\source\repos\LCAMP\Daten\DHBW CAD-Data\RegularWheel\Stl-Step-Dateien\Regular_Wheel_Star_24_84.STL" scale="0.001 0.001 0.001" />
      </geometry>
      <material name="drive_rr_Regular-Wheel_material">
        <color rgba="1 1 1 0.7" />
      </material>
    </visual>
    <visual name="Wheel-Hub-Cup">
      <origin rpy="0 0 0" xyz="0 0 0.029" />
      <geometry>
        <mesh filename="d:\Users\kdRupp\source\repos\LCAMP\Daten\DHBW CAD-Data\Wheels\STL-Step-Dateien\Hub_Cup_8.STL" scale="0.001 0.001 0.001" />
      </geometry>
      <material name="drive_rr_Regular-Wheel_material">
        <color rgba="1 1 1 0.7" />
      </material>
    </visual>
    <visual name="Tire">
      <origin rpy="0 0 0" xyz="0 0 0.003" />
      <geometry>
        <mesh filename="d:\Users\kdRupp\source\repos\LCAMP\Daten\DHBW CAD-Data\RegularWheel\Stl-Step-Dateien\Tire_96.STL" scale="0.001 0.001 0.001" />
      </geometry>
      <material name="drive_rr_Regular-Wheel_material">
        <color rgba="0 0 0 1" />
      </material>
    </visual>
    <collision>
      <geometry>
        <cylinder length="1" radius="1" />
      </geometry>
    </collision>
  </link>
  <link name="jdrive_rr">
    <inertial>
      <origin rpy="0 0 0" xyz="0 0 0" />
      <mass value="50" />
      <inertia ixx="3.12E-05" ixy="0" ixz="0" iyy="3.12E-05" iyz="0" izz="57.60000000000001" />
    </inertial>
    <visual>
      <geometry>
        <cylinder length="0.024" radius="0.048" />
      </geometry>
      <material name="jdrive_rr_material">
        <color rgba="0.6 0.7 0.8 0.6" />
      </material>
    </visual>
    <collision>
      <geometry>
        <cylinder length="0.024" radius="0.048" />
      </geometry>
    </collision>
  </link>
  <link name="drive_fl_Omni-Wheel">
    <inertial>
      <origin rpy="0 0 0" xyz="0 0 0" />
      <mass value="100" />
      <inertia ixx="4.7466666666666664E-05" ixy="0" ixz="0" iyy="0.0004016333333333333" iyz="0" izz="0.00038083333333333323" />
    </inertial>
    <visual name="Wheel-Hub">
      <origin rpy="0 0 0" xyz="0 0 0" />
      <geometry>
        <mesh filename="d:\Users\kdRupp\source\repos\LCAMP\Daten\DHBW CAD-Data\Wheels\STL-Step-Dateien\Wheel_Hub.STL" scale="0.001 0.001 0.001" />
      </geometry>
      <material name="drive_fl_Omni-Wheel_material">
        <color rgba="1 1 1 0.7" />
      </material>
    </visual>
    <visual name="rim_inner">
      <origin rpy="0 0 0" xyz="0 0 0.003" />
      <geometry>
        <mesh filename="d:\Users\kdRupp\source\repos\LCAMP\Daten\DHBW CAD-Data\RegularWheel\Stl-Step-Dateien\Regular_Wheel_Star_30_84.STL" scale="0.001 0.001 0.001" />
      </geometry>
      <material name="drive_fl_Omni-Wheel_material">
        <color rgba="1 1 1 0.7" />
      </material>
    </visual>
    <visual name="rim_outer">
      <origin rpy="0 0 0" xyz="0 0 0.025" />
      <geometry>
        <mesh filename="d:\Users\kdRupp\source\repos\LCAMP\Daten\DHBW CAD-Data\RegularWheel\Stl-Step-Dateien\Regular_Wheel_Star_24_84.STL" scale="0.001 0.001 0.001" />
      </geometry>
      <material name="drive_fl_Omni-Wheel_material">
        <color rgba="1 1 1 0.7" />
      </material>
    </visual>
    <visual name="Roller">
      <origin rpy="0 0 0" xyz="0 0 0.029" />
      <geometry>
        <mesh filename="d:\Users\kdRupp\source\repos\LCAMP\Daten\DHBW CAD-Data\Wheels\STL-Step-Dateien\Hub_Cup_8.STL" scale="0.001 0.001 0.001" />
      </geometry>
      <material name="drive_fl_Omni-Wheel_material">
        <color rgba="1 1 1 0.7" />
      </material>
    </visual>
    <visual name="Roller">
      <origin rpy="0 0 0" xyz="0 0 0.003" />
      <geometry>
        <mesh filename="d:\Users\kdRupp\source\repos\LCAMP\Daten\DHBW CAD-Data\RegularWheel\Stl-Step-Dateien\Tire_96.STL" scale="0.001 0.001 0.001" />
      </geometry>
      <material name="drive_fl_Omni-Wheel_material">
        <color rgba="0 0 0 1" />
      </material>
    </visual>
    <collision>
      <geometry>
        <cylinder length="1" radius="1" />
      </geometry>
    </collision>
  </link>
  <link name="jdrive_fl">
    <inertial>
      <origin rpy="0 0 0" xyz="0 0 0" />
      <mass value="50" />
      <inertia ixx="3.12E-05" ixy="0" ixz="0" iyy="3.12E-05" iyz="0" izz="57.60000000000001" />
    </inertial>
    <visual>
      <geometry>
        <cylinder length="0.024" radius="0.048" />
      </geometry>
      <material name="jdrive_fl_material">
        <color rgba="0.6 0.7 0.8 0.6" />
      </material>
    </visual>
    <collision>
      <geometry>
        <cylinder length="0.024" radius="0.048" />
      </geometry>
    </collision>
  </link>
  <link name="drive_fr_Omni-Wheel">
    <inertial>
      <origin rpy="0 0 0" xyz="0 0 0" />
      <mass value="100" />
      <inertia ixx="4.7466666666666664E-05" ixy="0" ixz="0" iyy="0.0004016333333333333" iyz="0" izz="0.00038083333333333323" />
    </inertial>
    <visual name="Wheel-Hub">
      <origin rpy="0 0 0" xyz="0 0 0" />
      <geometry>
        <mesh filename="d:\Users\kdRupp\source\repos\LCAMP\Daten\DHBW CAD-Data\Wheels\STL-Step-Dateien\Wheel_Hub.STL" scale="0.001 0.001 0.001" />
      </geometry>
      <material name="drive_fr_Omni-Wheel_material">
        <color rgba="1 1 1 0.7" />
      </material>
    </visual>
    <visual name="rim_inner">
      <origin rpy="0 0 0" xyz="0 0 0.003" />
      <geometry>
        <mesh filename="d:\Users\kdRupp\source\repos\LCAMP\Daten\DHBW CAD-Data\RegularWheel\Stl-Step-Dateien\Regular_Wheel_Star_30_84.STL" scale="0.001 0.001 0.001" />
      </geometry>
      <material name="drive_fr_Omni-Wheel_material">
        <color rgba="1 1 1 0.7" />
      </material>
    </visual>
    <visual name="rim_outer">
      <origin rpy="0 0 0" xyz="0 0 0.025" />
      <geometry>
        <mesh filename="d:\Users\kdRupp\source\repos\LCAMP\Daten\DHBW CAD-Data\RegularWheel\Stl-Step-Dateien\Regular_Wheel_Star_24_84.STL" scale="0.001 0.001 0.001" />
      </geometry>
      <material name="drive_fr_Omni-Wheel_material">
        <color rgba="1 1 1 0.7" />
      </material>
    </visual>
    <visual name="Roller">
      <origin rpy="0 0 0" xyz="0 0 0.029" />
      <geometry>
        <mesh filename="d:\Users\kdRupp\source\repos\LCAMP\Daten\DHBW CAD-Data\Wheels\STL-Step-Dateien\Hub_Cup_8.STL" scale="0.001 0.001 0.001" />
      </geometry>
      <material name="drive_fr_Omni-Wheel_material">
        <color rgba="1 1 1 0.7" />
      </material>
    </visual>
    <visual name="Roller">
      <origin rpy="0 0 0" xyz="0 0 0.003" />
      <geometry>
        <mesh filename="d:\Users\kdRupp\source\repos\LCAMP\Daten\DHBW CAD-Data\RegularWheel\Stl-Step-Dateien\Tire_96.STL" scale="0.001 0.001 0.001" />
      </geometry>
      <material name="drive_fr_Omni-Wheel_material">
        <color rgba="0 0 0 1" />
      </material>
    </visual>
    <collision>
      <geometry>
        <cylinder length="1" radius="1" />
      </geometry>
    </collision>
  </link>
  <link name="jdrive_fr">
    <inertial>
      <origin rpy="0 0 0" xyz="0 0 0" />
      <mass value="50" />
      <inertia ixx="3.12E-05" ixy="0" ixz="0" iyy="3.12E-05" iyz="0" izz="57.60000000000001" />
    </inertial>
    <visual>
      <geometry>
        <cylinder length="0.024" radius="0.048" />
      </geometry>
      <material name="jdrive_fr_material">
        <color rgba="0.6 0.7 0.8 0.6" />
      </material>
    </visual>
    <collision>
      <geometry>
        <cylinder length="0.024" radius="0.048" />
      </geometry>
    </collision>
  </link>
  <link name="Sensorbox front_sbFront">
    <inertial>
      <origin rpy="0 0 0" xyz="0 0 0" />
      <mass value="100" />
      <inertia ixx="4.7466666666666664E-05" ixy="0" ixz="0" iyy="0.0004016333333333333" iyz="0" izz="0.00038083333333333323" />
    </inertial>
    <visual>
      <geometry>
        <mesh filename="d:\Users\kdRupp\source\repos\LCAMP\Daten\DHBW CAD-Data\SensorSystems\STL-Step-Files\Sensorbox curved_15.STL" scale="0.001 0.001 0.001" />
      </geometry>
      <material name="Sensorbox front_sbFront_material">
        <color rgba="0.5019607843137255 0.5019607843137255 0.5019607843137255 1" />
      </material>
    </visual>
    <collision>
      <geometry>
        <mesh filename="d:\Users\kdRupp\source\repos\LCAMP\Daten\DHBW CAD-Data\SensorSystems\STL-Step-Files\Sensorbox curved_15.STL" scale="0.001 0.001 0.001" />
      </geometry>
    </collision>
  </link>
  <link name="Sensorbox rear_sbRear">
    <inertial>
      <origin rpy="0 0 0" xyz="0 0 0" />
      <mass value="100" />
      <inertia ixx="4.7466666666666664E-05" ixy="0" ixz="0" iyy="0.0004016333333333333" iyz="0" izz="0.00038083333333333323" />
    </inertial>
    <visual>
      <geometry>
        <mesh filename="d:\Users\kdRupp\source\repos\LCAMP\Daten\DHBW CAD-Data\SensorSystems\STL-Step-Files\Sensorbox curved_15.STL" scale="0.001 0.001 0.001" />
      </geometry>
      <material name="Sensorbox rear_sbRear_material">
        <color rgba="0.5019607843137255 0.5019607843137255 0.5019607843137255 1" />
      </material>
    </visual>
    <collision>
      <geometry>
        <mesh filename="d:\Users\kdRupp\source\repos\LCAMP\Daten\DHBW CAD-Data\SensorSystems\STL-Step-Files\Sensorbox curved_15.STL" scale="0.001 0.001 0.001" />
      </geometry>
    </collision>
  </link>
  <link name="Sensorbox center_sbCenter">
    <inertial>
      <origin rpy="0 0 0" xyz="0 0 0" />
      <mass value="100" />
      <inertia ixx="4.7466666666666664E-05" ixy="0" ixz="0" iyy="0.0004016333333333333" iyz="0" izz="0.00038083333333333323" />
    </inertial>
    <visual>
      <geometry>
        <mesh filename="d:\Users\kdRupp\source\repos\LCAMP\Daten\DHBW CAD-Data\SensorSystems\STL-Step-Files\Sensorbox_small_64.STL" scale="0.001 0.001 0.001" />
      </geometry>
      <material name="Sensorbox center_sbCenter_material">
        <color rgba="0.5019607843137255 0.5019607843137255 0.5019607843137255 1" />
      </material>
    </visual>
    <collision>
      <geometry>
        <mesh filename="d:\Users\kdRupp\source\repos\LCAMP\Daten\DHBW CAD-Data\SensorSystems\STL-Step-Files\Sensorbox_small_64.STL" scale="0.001 0.001 0.001" />
      </geometry>
    </collision>
  </link>
  <joint name="joint_drive_rl" type="continuous">
    <origin rpy="1.5707963267948966 0 0" xyz="-0.1 0.085 0" />
    <parent link="center" />
    <child link="jdrive_rl" />
    <axis xyz="0 0 1" />
    <dynamics damping="0.1" friction="0.1" />
  </joint>
  <joint name="joint_drive_rl_Regular-Wheel" type="fixed">
    <origin rpy="0 3.141592653589793 0" xyz="0 0 -0.012" />
    <parent link="jdrive_rl" />
    <child link="drive_rl_Regular-Wheel" />
    <axis xyz="0 0 1" />
    <dynamics damping="0.1" friction="0.1" />
  </joint>
  <joint name="joint_drive_rr" type="continuous">
    <origin rpy="-1.5707963267948966 0 0" xyz="-0.1 -0.085 0" />
    <parent link="center" />
    <child link="jdrive_rr" />
    <axis xyz="0 0 1" />
    <dynamics damping="0.1" friction="0.1" />
  </joint>
  <joint name="joint_drive_rr_Regular-Wheel" type="fixed">
    <origin rpy="0 3.141592653589793 0" xyz="0 0 -0.012" />
    <parent link="jdrive_rr" />
    <child link="drive_rr_Regular-Wheel" />
    <axis xyz="0 0 1" />
    <dynamics damping="0.1" friction="0.1" />
  </joint>
  <joint name="joint_drive_fl" type="continuous">
    <origin rpy="1.5707963267948966 0 0" xyz="0.1 0.085 0" />
    <parent link="center" />
    <child link="jdrive_fl" />
    <axis xyz="0 0 1" />
    <dynamics damping="0.1" friction="0.1" />
  </joint>
  <joint name="joint_drive_fl_Omni-Wheel" type="fixed">
    <origin rpy="0 3.141592653589793 0" xyz="0 0 -0.012" />
    <parent link="jdrive_fl" />
    <child link="drive_fl_Omni-Wheel" />
    <axis xyz="0 0 1" />
    <dynamics damping="0.1" friction="0.1" />
  </joint>
  <joint name="joint_drive_fr" type="continuous">
    <origin rpy="-1.5707963267948966 0 0" xyz="0.1 -0.085 0" />
    <parent link="center" />
    <child link="jdrive_fr" />
    <axis xyz="0 0 1" />
    <dynamics damping="0.1" friction="0.1" />
  </joint>
  <joint name="joint_drive_fr_Omni-Wheel" type="fixed">
    <origin rpy="0 3.141592653589793 0" xyz="0 0 -0.012" />
    <parent link="jdrive_fr" />
    <child link="drive_fr_Omni-Wheel" />
    <axis xyz="0 0 1" />
    <dynamics damping="0.1" friction="0.1" />
  </joint>
  <joint name="link_Sensorbox front_sbFront" type="fixed">
    <origin rpy="-1.5707963267948966 -1.5707963267948966 0" xyz="0.15 0 -0.032" />
    <parent link="center" />
    <child link="Sensorbox front_sbFront" />
    <axis xyz="0 0 1" />
    <dynamics damping="0.1" friction="0.1" />
  </joint>
  <joint name="link_Sensorbox rear_sbRear" type="fixed">
    <origin rpy="1.5707963267948966 -1.5707963267948966 0" xyz="-0.15 0 -0.032" />
    <parent link="center" />
    <child link="Sensorbox rear_sbRear" />
    <axis xyz="0 0 1" />
    <dynamics damping="0.1" friction="0.1" />
  </joint>
</robot>